Workbook

Sheet Life Cycle Data Worksheet
A1: General Project Information | J1: Project Managers | L1: Project Leaders | N1: Project Types | P1: Special Types | Q1: Compensation | R1: Category
A2: Project Name: | C2: Muncie Family Physicians | G2: Project Start Date: | H2: 46209 | J2: (Select) | L2: (Select) | N2: (Select) | P2: (Select) | Q2: (Select)
A3: Project Location: | C3: (from Initial Information) | G3: Project Number: | H3: (Must be Requested) | J3: Andrea Bowman, AIA | L3: Justin Aubert, AIA | N3: Consolidation | P3: (None) | Q3: (Schedule E) | R3: If < 10,000S.F.
C4: (from Initial Information) | J4: Sean Johnson, AIA | N4: Contraction | P4: Feasibility Stage | Q4: (Schedule F) | R4: If < 10,000S.F.
A5: Project Group: | C5: (Select) | G5: Project Manager: | H5: (Select) | N5: Expansion | P5: Architectural Site Plan | Q5: Percentage Fee
A6: Project Type: | C6: (Select) | G6: Project Leader: | H6: (Select) | N6: New Site | P6: Preliminary Site Plan | Q6: Stipulated Fee
A7: Special Type: | C7: (Select) | G7: UHG DE Regional Rep.: | H7: (from Initial Information) | N7: Ground Up | P7: One-off | Q7: Negotiated Fee
A8: Compensation: | C8: (Select) | G8: UHG Regional PM Rep.: | H8: (from Initial Information) | N8: Tenant Build-out | P8: Infrastructure/MDF
A9: Current Project Status | N9: Remodel/Renovation | P9: Refresh
A10: Current Phase: | C10: (Select) | E10: Issue(s): | F10: ='Project Tracking Report'!F10 -> Deficiency Report | N10: Relocation
A11: Completion %: | C11: (Consult w/Project Leader) | N11: Split-Relocation
A12: Completion Date: | C12: (from Design Schedule)
A13: At Risk: | C13: (Select)
A15: Scope Description | J15: Phases | M15: Design Consultants | P15: Architect's Supplemental Services
A16: (from Initial Information) Must be refined/discussed to create clear understanding in Project Initiation Phase | J16: (Select) | M16: (Select) | P16: (Select)
J17: Project Initiation | P17: 3D scanning services/digital imaging and associated travel/management
J18: FS -Kick-off | P18: Field Measurement and Site Due Diligence Report
J19: FS_Scope Interview | P19: Civil Engineering
J20: FS-Preliminary Program | P20: Landscape Design
J21: FS-Scenario Development | P21: MEP Engineering
J22: FS-Utilization Analysis | P22: On-Site Project Representation
J23: Schematic Design | M23: Supplemental Service Consultants | P23: Commissioning
A24: Project S.F.: | C24: Existing (S.F.): | D24: (TBD) | F24: % of Existing | J24: Design Development | M24: (Architect) | P24: Sustainable Project Services pursuant to Section 3.1.3
B25: xx,xxx | C25: New (S.F.): | D25: (TBD) | F25: Conditions Reused: | H25: (Requested Data) | J25: Construction Documents | M25: Consultant | P25: Historic Preservation
A26: Project Sustainability Objectives | J26: Bidding/Permitting | P26: Other Services provided by Specialty Consultants
A27: (from Initial Information) | J27: Construction Administration | P27: Post Occupancy Evaluation
J28: Project Close-out | P28: Other Supplemental Services (Listed Below):
G29: Certification Req'd.: | H29: (Select) | J29: Post Occupancy
A30: Budget (Cost of the Work) | E30: Project Schedule Information (Initial) | J30: Warranty Period
A31: Original COW: | C31: (from Initial Information) | E31: Project Start Date: | H31: =H2 -> 46209
A32: DD COW: | C32: (TBD) | E32: Design Start Date: | H32: (Date of Purchase Order) | J32: Owner's Consultants and Contractors
A33: CD COW: | C33: (TBD) | E33: Design Completion Date: | H33: (from Design Schedule) | J33: (Select)
A34: Bid Amount: | C34: (TBD) | E34: Construction Start Date: | H34: (from Initial Information) | J34: Furniture
A35: Final COW: | C35: (TBD) | E35: Substantial Completion Date: | H35: (from Initial Information) | J35: Flooring
J36: Sound Masking
A37: Design Consultants (Basic Services) | E37: Supplemental Consulting Services (if Required) | J37: Artwork/Branding
A38: Mechanical: | C38: (Select) | E38: (Select) | H38: (Architect) | J38: Security (Owner internal and Business teams)
A39: Contact: | E39: (Select) | H39: (Architect) | J39: Audio Visual
A40: Electrical: | C40: (Select) | E40: (Select) | H40: (Architect) | J40: Signage
A41: Contact: | E41: (Select) | H41: (Architect) | J41: Medical Equipment
...

Sheet Design Schedule
A1: Project Design Schedule | J1: Project Design Schedule | T1: 1.0 SERVICE LEVEL AGREEMENT FRAMEWORK: Timeframe expectations by Project Type (Business Days)
A2: Project Name: | C2: ='Life Cycle Data Worksheet'!C2 -> Muncie Family Physicians | G2: Project Start Date: | H2: ='Life Cycle Data Worksheet'!H2 -> 46209 | K2: PROJECT PHASE | M2: DURATION (Days) | N2: DESIGN MILESTONE DELIVERY DATE | Q2: ACTUAL DELIVERY DATE | R2: REVISION | T2: The range of business days assumes the lesser number of days applies to the lower end of the square footage
A3: Project Location: | C3: ='Life Cycle Data Worksheet'!C3 -> (from Initial Information) | G3: Project Number: | H3: ='Life Cycle Data Worksheet'!H3 -> (Must be Requested) | K3: Owner Progress Review 1 | T3: category and the longer time frame applies to the higher end of the square footage category
C4: ='Life Cycle Data Worksheet'!C4 -> (from Initial Information) | K4: (Architectural, Furniture & Medical Equipment, | T4: Phase | U4: New Location / Relocation | V4: Remodel / Expansion | W4: Refresh / Infrastructure
A5: Project Group: | C5: ='Life Cycle Data Worksheet'!C5 -> (Select) | G5: Project Manager: | H5: ='Life Cycle Data Worksheet'!H5 -> (Select) | K5: and Millwork Elevations) | T5: Project Kick-off | U5: 1 | V5: 1 | W5: 1
A6: Project Type: | C6: ='Life Cycle Data Worksheet'!C6 -> (Select) | G6: Project Leader: | H6: ='Life Cycle Data Worksheet'!H6 -> (Select) | K6: Peer Design Review 2 | T6: Scope Review | U6: 1–5 | V6: 1 | W6: 1
A7: Special Type: | C7: ='Life Cycle Data Worksheet'!C7 -> (Select) | G7: UHG DE Regional Rep.: | H7: ='Life Cycle Data Worksheet'!H7 -> (from Initial Information) | K7: Owner Progress Review 2 | T7: Scenario Development | U7: 5–10 | V7: 5–10 | W7: 5
A8: Compensation: | C8: ='Life Cycle Data Worksheet'!C8 -> (Select) | G8: UHG Regional PM Rep.: | H8: ='Life Cycle Data Worksheet'!H8 -> (from Initial Information) | K8: (Discuss Power & Data Requirements and | T8: Utilization Analyses | U8: 2–10 | V8: 2–5 | W8: 1–2
B9: PROJECT PHASE | D9: DURATION (Days) | E9: DESIGN MILESTONE DELIVERY DATE | H9: ACTUAL DELIVERY DATE | I9: REVISION | K9: design revisions) | T9: Site Due Diligence | U9: 5–10 | V9: 5 | W9: 5
B10: Project Initiation | K10: QA/QC Review 1 | T10: Detailed Programming | U10: 5 | V10: 5 | W10: 5
B11: Project Kick-off | K11: Owner Progress Review 3 | T11: Preliminary Floor Plan / Schematic Design Documents | U11: 5–10 | V11: 5–10 | W11: 5
B12: Scope Review/Clarification | K12: (Finalize Power & Data Plans, Finishes, and | T12: Design Development Phase | U12: 15 | V12: 10–15 | W12: 5–10
B13: Budget Review/Clarification | K13: design revisions) | T13: Construction Docs | U13: 15–20 | V13: 15–20 | W13: 15
B14: Supplemental and/or Additional Services | K14: Owner Consultant Coordination | T14: Permitting / Bidding | U14: 15–20 | V14: 15 | W14: 15
B15: Design Schedule | K15: Design Exceptions (noted or Approved) | T15: Some projects may warrant accelerated SLA timelines which will be mutually agreed to by Firm and Owner.
B16: Site Visit? | K16: Budget Review/Clarification
B17: Proposed Compensation | K17: DD Phase Submittal Date | T17: Management of the project schedule, including the internal approval process, is the responsibility of the Owner’s Project Manager, with Architect
B18: Service Order Submittal Date | K18: DD Phase Approval Date | T18: having responsibility for design delivery components of the overall schedule. The timeframe expectations are intended to be adequate and appropriate
B19: Service Order Approval Date | K19: Construction Documents | T19: for Architect to deliver its services to an acceptable level by the owner to move forward. Incomplete data, untimely additions, or untimely approvals
B20: Site Planning Services | K20: Construction Documents | T20: may result in extensions of the project schedule. However, incomplete drawings, missed design intent or functionality will not warrant additional time
B21: Project Kick-off | K21: Specifications | T21: to the Architect.
B22: Document Verification | K22: Owner's Consultant's Work
B23: Proposed Compensation | K23: (Incorporation) | T23: From SOW General Services:
B24: Service Order Submittal DAte | K24: Life Safety Plan | T24: 4.2.1 The Architect shall submit for the Owner's approval a schedule for the performance of the Architect's services, and the services of Owner
B25: Service Order Approval Date | K25: 50 % CD Package Review Meeting (ground up Projects only) | T25: provided consultants, which initially shall be consistent with the time periods established in SLA Exhibit and which shall be adjusted by mutual
B26: Design Documentation | K26: up Projects Only) | T26: written agreement if necessary, as the project proceeds. This schedule shall include allowances for periods of time required for Owner's review,
B27: Architectural/Preliminary Plan Submittal Date | K27: Final Cost of Work Adjustments | T27: the performance of the Owners consultants, and for approval of submissions by authorities having jurisdiction over the Project. Time limits
B28: Architectural/Preliminary Plan Approval Date | K28: Preparation of Bidding Information (w/DE) | T28: established by the Schedule approved by the Owner shall not, except for reasonable cause, be exceeded by the Architect or the Owner.
B29: Feasibility Stage Services | K29: Clash Detection
B30: Feasibility Kick-off | K30: Final Code Review | T30: From SOW Basic Services:
B31: Feasibility Scope Interview | K31: QA/QC Review 2 | T31: As soon as practicable after the date of the Service Agreement, the Architect shall submit for the Owner’s approval a schedule for the performance
B32: Preliminary Program | K32: 90% CD Package Review Meeting (as determined by Owner) | T32: of the Architect’s services complying with the Owner’s preliminary schedule. The schedule initially shall include anticipated dates for the
B33: Scenario Development | T33: commencement of construction and for Substantial Completion of the Work as set forth in the Initial Information. The schedule shall include
B34: Utilization Analysis | K34: Final Pick-ups | T34: commencement of construction and for Substantial Completion of the Work as set forth in the Initial Information. The schedule shall include
B35: Feasibility Phase Submittal Date | K35: CD Phase Submittal Date | T35: allowances for periods of time required for the Owner’s review, for the performance of the Owner’s consultants, and for approval of submissions by
B36: Feasibility Phase Approval Date | K36: CD Phase Approval Date | T36: authorities having jurisdiction over the Project. Once approved by the Owner, time limits established by the schedule shall not, except for reasonable
B37: Schematic Design | J37: Bidding and Permitting Phase | T37: cause, be exceeded by the Architect or Owner. With the Owner’s approval, the Architect shall adjust the schedule, if necessary, as the Project proceeds
B38: Site Due Diligence Report | K38: Bid Time | T38: until the commencement of construction.
B39: Field Measurement | K39: Permit Submittal
B40: Program Summary Document | K40: Permit Review/Response | T40: The Design Milestone Dates are the dates by which the Architect shall be obligated to complete each phase of its design
...

Sheet Compensation
A1: Project Compensation Data | J1: Project Managers | L1: Project Leaders | N1: Project Types | P1: Special Types | Q1: Compensation | R1: Category
A2: Project Name: | C2: ='Life Cycle Data Worksheet'!C2 -> Muncie Family Physicians | G2: Project Start Date: | H2: ='Life Cycle Data Worksheet'!H2 -> 46209 | J2: (Select) | L2: (Select) | N2: (Select) | P2: (Select) | Q2: (Select)
A3: Project Location: | C3: ='Life Cycle Data Worksheet'!C3 -> (from Initial Information) | G3: Project/S.O. Number: | H3: ='Life Cycle Data Worksheet'!H3 -> (Must be Requested) | J3: Andrea Bowman, AIA | L3: Justin Aubert, AIA | N3: Consolidation | P3: (None) | Q3: (Schedule E) | R3: If < 10,000S.F.
C4: ='Life Cycle Data Worksheet'!C4 -> (from Initial Information) | J4: Sean Johnson, AIA | N4: Contraction | P4: Feasibility Stage | Q4: (Schedule F) | R4: If < 10,000S.F.
N5: Expansion | P5: Architectural Site Plan | Q5: Percentage Fee
N6: New Site | P6: Preliminary Site Plan | Q6: Stipulated Fee
A7: Fee for Basic Servces (Architectural and Interior Design) | N7: Ground Up | P7: One-off | Q7: Negotiated Fee
A8: Project S.F.: | C8: Compensation | N8: Tenant Build-out | P8: Infrastructure/MDF
B9: ='Life Cycle Data Worksheet'!B25 -> xx,xxx | D9: Feasibility Stage | F9: SD Thru DD | H9: CD Thru Closeout | N9: Remodel/Renovation | P9: Refresh
C10: Stipulated Sum | D10: Enter | E10: Amount | F10: Enter | G10: Amount | H10: (Enter Amount) | N10: Relocation
C11: Percentage Basis | D11: N/A | F11: Enter | G11: % | H11: (Enter Percentage) | N11: Split-Relocation
C12: Other | D12: Enter | E12: N.T.E. | F12: Enter | G12: N.T.E. | H12: (Enter Amount) N.T.E.
A13: Design Consultants Compensation
C14: Basis for Compensation | D14: or | E14: Enter Amount
A15: Mechanical | J15: Phases | M15: Design Consultants | P15: Architect's Supplemental Services
J16: (Select) | M16: (Select) | P16: (Select)
A17: Electrical | J17: Project Initiation | P17: 3D scanning services/digital imaging and associated travel/management
J18: FS -Kick-off | P18: Field Measurement and Site Due Diligence Report
A19: Structural | J19: FS_Scope Interview | P19: Civil Engineering
J20: FS-Preliminary Program | P20: Landscape Design
A21: Civil (if Required) | J21: FS-Scenario Development | P21: MEP Engineering
J22: FS-Utilization Analysis | P22: On-Site Project Representation
A23: Basic Service Exception (if any) | J23: Schematic Design | M23: Supplemental Service Consultants | P23: Commissioning
J24: Design Development | M24: (Architect) | P24: Sustainable Project Services pursuant to Section 3.1.3
J25: Construction Documents | M25: Consultant | P25: Historic Preservation
A26: Supplemental Consulting Services (if Required) | J26: Bidding/Permitting | P26: Other Services provided by Specialty Consultants
C27: Basis for Compensation | D27: or | E27: Enter Amount | J27: Construction Administration | P27: Post Occupancy Evaluation
J28: Project Close-out | P28: Other Supplemental Services (Listed Below):
J29: Post Occupancy
J30: Warranty Period
A31: Additional Services (if any)
C32: Basis for Compensation | D32: or | E32: Enter Amount | J32: Owner's Consultants and Contractors
J33: (Select)
J34: Furniture
J35: Flooring
J36: Sound Masking
J37: Artwork/Branding
J38: Security (Owner internal and Business teams)
J39: Audio Visual
A40: Reimbursable Expenses (Travel, Permit Fees and/or Field Office) | J40: Signage
...

Sheet Service Order
A1: AIA Document B221 - Service Order | K1: AIA Document B221 - Service Order | U1: AIA Document B221 - Service Order
A2: Service Order No.: | C2: Provided by CBRE PM | N2: Feasibility Phase: | P2: Schematic through | R2: Construction Development | U2: Other Supplemental Services (Listed Below): | AB2: Responsibility
A3: Service Order Date: | C3: Use Date of Project Engagement Meeting | P3: Design Development | R3: through Closeout Services: | U3: List Other Service(s) | Z3: Not Provided
P4: Phase:
A5: Owner: | B5: United HealthCare Services, Inc. | K5: Basic Services
B6: 9700 Healthcare Lane | K6: Consultants:
B7: Minnetonka, MN 55343 | K7: (MEP&Structural)
A8: Architect: | B8: Grace Healthcare Studios, LLC | E8: Grace Healthcare Studios USA, LLC | H8: One for Mississippi! | K8: ='Life Cycle Data Worksheet'!C38 -> (Select) | U8: The Architect shall provide Construction Administration Services exceeding the limits set forth in Exhibit "A" Scope of
B9: 501 Government Street | U9: Work as Additional Services: | X9: (Not sure what to put here)
B10: Suite 200 | K10: ='Life Cycle Data Worksheet'!C40 -> (Select) | U10: ARTICLE 3 DATE OF COMMENCEMENT AND SUBSTANTIAL COMPLETION
B11: Baton Rouge, LA 70802 | U11: Commencement of Construction Date: | Y11: ='Life Cycle Data Worksheet'!H34 -> (from Initial Information)
A12: Need to Verify which states require which corporation name (per Legal) | K12: ='Life Cycle Data Worksheet'!C42 -> (Select) | U12: Substantial Completion Date: | Y12: ='Life Cycle Data Worksheet'!H35 -> (from Initial Information)
A13: Project Name: | B13: ='Life Cycle Data Worksheet'!C2 -> Muncie Family Physicians | U13: ARTICLE 4.1 COMPENSATION | X13: (per Exhibits E & F of B121)
A14: Location: | B14: ='Life Cycle Data Worksheet'!C3 -> (from Initial Information) | K14: Supplemental Services | X14: Feasibility Phase: | Z14: Schematic through | AB14: Construction Development
B15: ='Life Cycle Data Worksheet'!C4 -> (from Initial Information) | K15: Consultants: | X15: (if applicable) | Z15: Design Development | AB15: through Closeout Services: | AF15: Compensation (From Exhibits E or F)
A16: Project Description: | K16: ='Life Cycle Data Worksheet'!H38 -> (Architect) | Z16: Phase: | AF16: N/A
A17: ='Life Cycle Data Worksheet'!A16 -> (from Initial Information) Must be refined/discussed to create clear understanding in Project Initiation Phase | K17: ='Life Cycle Data Worksheet'!H39 -> (Architect) | U17: Stipulated Sum | X17: (Insert Amount) | Z17: N/A | AB17: N/A | AF17: (Insert Amount)
K18: ='Life Cycle Data Worksheet'!H40 -> (Architect) | U18: (Insert Amount) | AF18: (Insert %)
K19: ='Life Cycle Data Worksheet'!H41 -> (Architect) | U19: Percentage Basis | X19: N/A | Z19: (Insert %) | AB19: (Insert %)
K20: ='Life Cycle Data Worksheet'!H42 -> (Architect) | U20: (Insert % Amount) | Z20: % of the Owner's budget for the Cost of the Work, as
A21: Master Agreement Dated: | D21: 45944 | E21: Line 1 of B121 - 2018 | K21: ='Life Cycle Data Worksheet'!H43 -> (Architect) | Z21: calculated in accordance with Section 4.4
D22: 46023 | E22: Article 1.1 B121 - 2018 | K22: ARTICLE 2 SERVICES UNDER THIS SERVICE ORDER | U22: Other
A23: ARTICLE 1 INITIAL INFORMATION | K23: Basic Services Exceptions: | U23: (Describe Method)
A24: Initial Information: | C24: See Attachment "X": Project Scope Document | K24: Feasibility Phase Exceptions: | N24: (NONE) or List
C25: See Attachment "X": Project Design Schedule | U25: 4.2 For Additional Services:
A26: Sustainable Objective: | C26: ='Life Cycle Data Worksheet'!A27 -> (from Initial Information) | K26: SD thru DD Exceptions: | N26: (NONE) or List | U26: (Basis of Compensation) | X26: See Attachment "X" Additional Services and/or Reimbursable Expenses
A27: Certification Required: | C27: ='Life Cycle Data Worksheet'!H29 -> (Select) | U27: 4.3 Reimbursable Expenses: | X27: See Attachment "X" Additional Services and/or Reimbursable Expenses
K28: CD thru Closeout Exceptions: | N28: (NONE) or List | U28: (Amount of Compensation)
D29: Feasibility Phase: | F29: Schematic through | H29: Construction Development | U29: 4.4 | V29: Needs Editing - Percentages do not equal 100%
F30: Design Development | H30: through Closeout Services: | U30: ARTICLE 5 INSURANCE | X30: (per B121 Master Agreement)
F31: Phase: | K31: Supplemental and Additional Services: | U31: ARTICLE 6 PARTY REPRESENTATIVES
A32: Owner's Consultants: | P32: Responsibility | U32: UHG Design Experience Regional Representative:
A33: ='Life Cycle Data Worksheet'!A45 -> (Select) | K33: Supplemental Services | P33: (Architect, Owner or Not Provided) | U33: (Name, address, contact info.) | X33: ='Life Cycle Data Worksheet'!H7 -> (from Initial Information)
A34: ='Life Cycle Data Worksheet'!A46 -> (Select) | K34: 3D scanning services/digital imaging and associated | P34: Not Provided | U34: UHG Regional Project Management Representative:
A35: ='Life Cycle Data Worksheet'!A47 -> (Select) | K35: travel/management | U35: (Name, address, contact info.) | X35: ='Life Cycle Data Worksheet'!H8 -> (from Initial Information)
A36: ='Life Cycle Data Worksheet'!A48 -> (Select) | K36: Field Measurement and Site Due Diligence Report | P36: Not Provided | U36: Architect Project Management Representative:
A37: ='Life Cycle Data Worksheet'!A49 -> (Select) | K37: Civil Engineering | P37: Not Provided | U37: (Name, address, contact info.) | X37: ='Life Cycle Data Worksheet'!H5 -> (Select)
A38: ='Life Cycle Data Worksheet'!A50 -> (Select) | K38: Landscape Design | P38: Not Provided | U38: Architects Project Representative:
A39: ='Life Cycle Data Worksheet'!E45 -> (Select) | K39: MEP Engineering | P39: Not Provided | U39: (Name, address, contact info.) | X39: ='Life Cycle Data Worksheet'!H6 -> (Select)
A40: ='Life Cycle Data Worksheet'!E46 -> (Select) | K40: On-Site Project Representation | P40: Not Provided | U40: ARTICLE 7 ATTACHMENTS AND EXHIBITS
...

Sheet Project Tracking Report
A1: Project Tracking Report | I1: Project Tracking Report | R1: Design Fee Reporting (Quarterly)
A2: Project Name: | C2: ='Life Cycle Data Worksheet'!C2 -> Muncie Family Physicians | G2: Project Start Date: | H2: ='Life Cycle Data Worksheet'!H2 -> 46209 | I2: Potential Project Risk and proposed Mitigation Strategies | R2: Format should match or exceed level of detail in Exhibit J and include any Owner requested changes
A3: Project Location: | C3: ='Life Cycle Data Worksheet'!C3 -> (from Initial Information) | G3: Project/S.O. Number: | H3: ='Life Cycle Data Worksheet'!H3 -> (Must be Requested) | J3: (Per Phase) | R3: Design Fees including all consultants by project, reimbursable costs and any additional services:
R4: Proposed/Budgeted Fees vs actual Fees per project:
A5: Project Group: | C5: ='Life Cycle Data Worksheet'!C5 -> (Select) | G5: Project Manager: | H5: ='Life Cycle Data Worksheet'!H5 -> (Select) | R5: Number of Staff and time spent on Owner's account: Per Phase)
A6: Project Type: | C6: ='Life Cycle Data Worksheet'!C6 -> (Select) | G6: Project Leader: | H6: ='Life Cycle Data Worksheet'!H6 -> (Select)
A7: Special Type: | C7: ='Life Cycle Data Worksheet'!C7 -> (Select) | G7: UHG DE Regional Rep.: | H7: ='Life Cycle Data Worksheet'!H7 -> (from Initial Information)
A8: Compensation: | C8: ='Life Cycle Data Worksheet'!C8 -> (Select) | G8: UHG Regional PM Rep.: | H8: ='Life Cycle Data Worksheet'!H8 -> (from Initial Information)
A9: Current Project Status | R9: The total number of requests and projects handled.
A10: Current Phase: | C10: ='Life Cycle Data Worksheet'!C10 -> (Select) | E10: Issue(s): | F10: =I11 -> Deficiency Report | R10: The percentage of requests that met the expected response times.
A11: Completion %: | C11: ='Life Cycle Data Worksheet'!C11 -> (Consult w/Project Leader) | I11: Deficiency Report | R11: Project name
A12: Completion Date: | C12: ='Life Cycle Data Worksheet'!C12 -> (from Design Schedule) | J12: (Per Phase) | R12: Brief description
A13: At Risk: | C13: ='Life Cycle Data Worksheet'!C13 -> (Select) | R13: Percentage of Existing Conditions/ walls (etc.) reused per project
R14: Scheduled Project phases
A15: Project Tracking per Phase | R15: Project Status
A16: Project Initiation Phase: | R16: Service Order requested, submittal dates and approval status
A17: Design Milestone Date: | C17: ='Design Schedule'!F18 -> 0 | G17: Submittal Date: | H17: ='Design Schedule'!H18 -> 0 | R17: Potential project risk and proposed mitigation strategies
A18: Submittal Attempts: | C18: (Manual Entry) | G18: Approval Date: | H18: ='Design Schedule'!F19 -> 0 | R18: Project team leader and contact point
A19: Approval Deficiencies: | C19: (Manual Entry from DR) | R19: Number of Staff and their percentage of time spent on Owner’s account
A20: No. of Staff | C20: (Phase Close-out Data) | G20: % Time spent on account: | H20: (Phase Close-out Data) | R20: Deficiency report
A21: Feasibility Stage: | R21: Project was or was not delivered according to the agreed-upon schedule, and budget at the final funding milestone
A22: Design Milestone Date: | C22: ='Design Schedule'!F35 -> 0 | G22: Submittal Date: | H22: ='Design Schedule'!H35 -> 0
A23: Submittal Attempts: | C23: (Manual Entry) | G23: Approval Date: | H23: ='Design Schedule'!F36 -> 0
A24: Approval Deficiencies: | R24: Architectural and MEP coordination issues/ misses
A25: No. of Staff | G25: % Time spent on account: | H25: (Phase Close-out Data) | R25: Number of Change Orders per project
A26: Schematic Design Phase:
A27: Design Milestone Date: | C27: ='Design Schedule'!F48 -> 0 | G27: Submittal Date: | H27: ='Design Schedule'!H48 -> 0 | R27: Number of RFIs per project- broken down by type (detailed Owner scope change, unforeseen conditions, Errors and Omissions)
A28: Submittal Attempts: | C28: (Manual Entry) | G28: Approval Date: | H28: ='Design Schedule'!F49 -> 0
A29: Approval Deficiencies: | C29: (Manual Entry from DR)
A30: No. of Staff | C30: (Phase Close-out Data) | G30: % Time spent on account: | H30: (Phase Close-out Data)
A31: Percentage of Existing Conditions/ walls (etc.) reused per project | E31: ='Life Cycle Data Worksheet'!H25 -> (Requested Data)
A32: Design Development Phase:
A33: Design Milestone Date: | C33: ='Design Schedule'!O17 -> 0 | G33: Submittal Date: | H33: ='Design Schedule'!Q17 -> 0 | I33: Schedule reduction (savings)
A34: Submittal Attempts: | C34: (Manual Entry) | G34: Approval Date: | H34: ='Design Schedule'!O18 -> 0 | J34: (Per Phase)
A35: Approval Deficiencies: | C35: (Manual Entry from DR)
A36: No. of Staff | C36: (Phase Close-out Data) | G36: % Time spent on account: | H36: (Phase Close-out Data)
A37: Percentage of Existing Conditions/ walls (etc.) reused per project | E37: ='Life Cycle Data Worksheet'!H25 -> (Requested Data)
A38: Construction Document Phase:
A39: Design Milestone Date: | C39: ='Design Schedule'!O35 -> 0 | G39: Submittal Date: | H39: ='Design Schedule'!Q35 -> 0 | I39: Cost Savings and applied strategies for cost savings
A40: Submittal Attempts: | C40: (Manual Entry) | G40: Approval Date: | H40: ='Design Schedule'!O36 -> 0 | J40: (Per Phase)
...
